Traceback (most recent call last):
  File "/anaconda3/lib/python3.7/site-packages/urllib3/connection.py", line 159, in _new_conn
    (self._dns_host, self.port), self.timeout, **extra_kw)
  File "/anaconda3/lib/python3.7/site-packages/urllib3/util/connection.py", line 57, in create_connection
    for res in socket.getaddrinfo(host, port, family, socket.SOCK_STREAM):
  File "/anaconda3/lib/python3.7/socket.py", line 748, in getaddrinfo
    for res in _socket.getaddrinfo(host, port, family, type, proto, flags):
socket.gaierror: [Errno 8] nodename nor servname provided, or not known

During handling of the above exception, another exception occurred:

Traceback (most recent call last):
  File "/anaconda3/lib/python3.7/site-packages/urllib3/connectionpool.py", line 600, in urlopen
    chunked=chunked)
  File "/anaconda3/lib/python3.7/site-packages/urllib3/connectionpool.py", line 354, in _make_request
    conn.request(method, url, **httplib_request_kw)
  File "/anaconda3/lib/python3.7/http/client.py", line 1229, in request
    self._send_request(method, url, body, headers, encode_chunked)
  File "/anaconda3/lib/python3.7/http/client.py", line 1275, in _send_request
    self.endheaders(body, encode_chunked=encode_chunked)
  File "/anaconda3/lib/python3.7/http/client.py", line 1224, in endheaders
    self._send_output(message_body, encode_chunked=encode_chunked)
  File "/anaconda3/lib/python3.7/http/client.py", line 1016, in _send_output
    self.send(msg)
  File "/anaconda3/lib/python3.7/http/client.py", line 956, in send
    self.connect()
  File "/anaconda3/lib/python3.7/site-packages/urllib3/connection.py", line 181, in connect
    conn = self._new_conn()
  File "/anaconda3/lib/python3.7/site-packages/urllib3/connection.py", line 168, in _new_conn
    self, "Failed to establish a new connection: %s" % e)
urllib3.exceptions.NewConnectionError: <urllib3.connection.HTTPConnection object at 0x11c3ae5f8>: Failed to establish a new connection: [Errno 8] nodename nor servname provided, or not known

During handling of the above exception, another exception occurred:

Traceback (most recent call last):
  File "/anaconda3/lib/python3.7/site-packages/requests/adapters.py", line 449, in send
    timeout=timeout
  File "/anaconda3/lib/python3.7/site-packages/urllib3/connectionpool.py", line 638, in urlopen
    _stacktrace=sys.exc_info()[2])
  File "/anaconda3/lib/python3.7/site-packages/urllib3/util/retry.py", line 398, in increment
    raise MaxRetryError(_pool, url, error or ResponseError(cause))
urllib3.exceptions.MaxRetryError: HTTPConnectionPool(host='api.openweathermap.org', port=80): Max retries exceeded with url: /data/2.5/forecast?APPID=08ce08de126e25469062d11550ee8e4c&q=New+York%2C+New+York&lang=en (Caused by NewConnectionError('<urllib3.connection.HTTPConnection object at 0x11c3ae5f8>: Failed to establish a new connection: [Errno 8] nodename nor servname provided, or not known'))

During handling of the above exception, another exception occurred:

Traceback (most recent call last):
  File "/anaconda3/lib/python3.7/site-packages/pyowm/commons/http_client.py", line 25, in get_json
    timeout=self.timeout, verify=self.verify_ssl_certs)
  File "/anaconda3/lib/python3.7/site-packages/requests/api.py", line 75, in get
    return request('get', url, params=params, **kwargs)
  File "/anaconda3/lib/python3.7/site-packages/requests/api.py", line 60, in request
    return session.request(method=method, url=url, **kwargs)
  File "/anaconda3/lib/python3.7/site-packages/requests/sessions.py", line 533, in request
    resp = self.send(prep, **send_kwargs)
  File "/anaconda3/lib/python3.7/site-packages/requests/sessions.py", line 646, in send
    r = adapter.send(request, **kwargs)
  File "/anaconda3/lib/python3.7/site-packages/requests/adapters.py", line 516, in send
    raise ConnectionError(e, request=request)
requests.exceptions.ConnectionError: HTTPConnectionPool(host='api.openweathermap.org', port=80): Max retries exceeded with url: /data/2.5/forecast?APPID=08ce08de126e25469062d11550ee8e4c&q=New+York%2C+New+York&lang=en (Caused by NewConnectionError('<urllib3.connection.HTTPConnection object at 0x11c3ae5f8>: Failed to establish a new connection: [Errno 8] nodename nor servname provided, or not known'))

During handling of the above exception, another exception occurred:

Traceback (most recent call last):
  File "weather.py", line 130, in <module>
    schedule.run_pending()
  File "/anaconda3/lib/python3.7/site-packages/schedule/__init__.py", line 493, in run_pending
    default_scheduler.run_pending()
  File "/anaconda3/lib/python3.7/site-packages/schedule/__init__.py", line 78, in run_pending
    self._run_job(job)
  File "/anaconda3/lib/python3.7/site-packages/schedule/__init__.py", line 131, in _run_job
    ret = job.run()
  File "/anaconda3/lib/python3.7/site-packages/schedule/__init__.py", line 411, in run
    ret = self.job_func()
  File "weather.py", line 124, in job
    message = generate_message(user['location'])
  File "weather.py", line 62, in generate_message
    fc = owm.three_hours_forecast(location)
  File "/anaconda3/lib/python3.7/site-packages/pyowm/weatherapi25/owm25.py", line 567, in three_hours_forecast
    _, json_data = self._wapi.cacheable_get_json(uri, params=params)
  File "/anaconda3/lib/python3.7/site-packages/pyowm/commons/http_client.py", line 87, in cacheable_get_json
    status_code, data = self.get_json(uri, params=params, headers=headers)
  File "/anaconda3/lib/python3.7/site-packages/pyowm/commons/http_client.py", line 29, in get_json
    raise api_call_error.APIInvalidSSLCertificateError(str(e))
pyowm.exceptions.api_call_error.APIInvalidSSLCertificateError: Exception in calling OWM Weather API.
Reason: HTTPConnectionPool(host='api.openweathermap.org', port=80): Max retries exceeded with url: /data/2.5/forecast?APPID=08ce08de126e25469062d11550ee8e4c&q=New+York%2C+New+York&lang=en (Caused by NewConnectionError('<urllib3.connection.HTTPConnection object at 0x11c3ae5f8>: Failed to establish a new connection: [Errno 8] nodename nor servname provided, or not known'))
Caused by: None
Traceback (most recent call last):
  File "/anaconda3/lib/python3.7/site-packages/urllib3/connection.py", line 159, in _new_conn
    (self._dns_host, self.port), self.timeout, **extra_kw)
  File "/anaconda3/lib/python3.7/site-packages/urllib3/util/connection.py", line 57, in create_connection
    for res in socket.getaddrinfo(host, port, family, socket.SOCK_STREAM):
  File "/anaconda3/lib/python3.7/socket.py", line 748, in getaddrinfo
    for res in _socket.getaddrinfo(host, port, family, type, proto, flags):
socket.gaierror: [Errno 8] nodename nor servname provided, or not known

During handling of the above exception, another exception occurred:

Traceback (most recent call last):
  File "/anaconda3/lib/python3.7/site-packages/urllib3/connectionpool.py", line 600, in urlopen
    chunked=chunked)
  File "/anaconda3/lib/python3.7/site-packages/urllib3/connectionpool.py", line 354, in _make_request
    conn.request(method, url, **httplib_request_kw)
  File "/anaconda3/lib/python3.7/http/client.py", line 1229, in request
    self._send_request(method, url, body, headers, encode_chunked)
  File "/anaconda3/lib/python3.7/http/client.py", line 1275, in _send_request
    self.endheaders(body, encode_chunked=encode_chunked)
  File "/anaconda3/lib/python3.7/http/client.py", line 1224, in endheaders
    self._send_output(message_body, encode_chunked=encode_chunked)
  File "/anaconda3/lib/python3.7/http/client.py", line 1016, in _send_output
    self.send(msg)
  File "/anaconda3/lib/python3.7/http/client.py", line 956, in send
    self.connect()
  File "/anaconda3/lib/python3.7/site-packages/urllib3/connection.py", line 181, in connect
    conn = self._new_conn()
  File "/anaconda3/lib/python3.7/site-packages/urllib3/connection.py", line 168, in _new_conn
    self, "Failed to establish a new connection: %s" % e)
urllib3.exceptions.NewConnectionError: <urllib3.connection.HTTPConnection object at 0x11e35b7f0>: Failed to establish a new connection: [Errno 8] nodename nor servname provided, or not known

During handling of the above exception, another exception occurred:

Traceback (most recent call last):
  File "/anaconda3/lib/python3.7/site-packages/requests/adapters.py", line 449, in send
    timeout=timeout
  File "/anaconda3/lib/python3.7/site-packages/urllib3/connectionpool.py", line 638, in urlopen
    _stacktrace=sys.exc_info()[2])
  File "/anaconda3/lib/python3.7/site-packages/urllib3/util/retry.py", line 398, in increment
    raise MaxRetryError(_pool, url, error or ResponseError(cause))
urllib3.exceptions.MaxRetryError: HTTPConnectionPool(host='api.openweathermap.org', port=80): Max retries exceeded with url: /data/2.5/forecast?APPID=08ce08de126e25469062d11550ee8e4c&q=New+York%2C+New+York&lang=en (Caused by NewConnectionError('<urllib3.connection.HTTPConnection object at 0x11e35b7f0>: Failed to establish a new connection: [Errno 8] nodename nor servname provided, or not known'))

During handling of the above exception, another exception occurred:

Traceback (most recent call last):
  File "/anaconda3/lib/python3.7/site-packages/pyowm/commons/http_client.py", line 25, in get_json
    timeout=self.timeout, verify=self.verify_ssl_certs)
  File "/anaconda3/lib/python3.7/site-packages/requests/api.py", line 75, in get
    return request('get', url, params=params, **kwargs)
  File "/anaconda3/lib/python3.7/site-packages/requests/api.py", line 60, in request
    return session.request(method=method, url=url, **kwargs)
  File "/anaconda3/lib/python3.7/site-packages/requests/sessions.py", line 533, in request
    resp = self.send(prep, **send_kwargs)
  File "/anaconda3/lib/python3.7/site-packages/requests/sessions.py", line 646, in send
    r = adapter.send(request, **kwargs)
  File "/anaconda3/lib/python3.7/site-packages/requests/adapters.py", line 516, in send
    raise ConnectionError(e, request=request)
requests.exceptions.ConnectionError: HTTPConnectionPool(host='api.openweathermap.org', port=80): Max retries exceeded with url: /data/2.5/forecast?APPID=08ce08de126e25469062d11550ee8e4c&q=New+York%2C+New+York&lang=en (Caused by NewConnectionError('<urllib3.connection.HTTPConnection object at 0x11e35b7f0>: Failed to establish a new connection: [Errno 8] nodename nor servname provided, or not known'))

During handling of the above exception, another exception occurred:

Traceback (most recent call last):
  File "weather.py", line 130, in <module>
    schedule.run_pending()
  File "/anaconda3/lib/python3.7/site-packages/schedule/__init__.py", line 493, in run_pending
    default_scheduler.run_pending()
  File "/anaconda3/lib/python3.7/site-packages/schedule/__init__.py", line 78, in run_pending
    self._run_job(job)
  File "/anaconda3/lib/python3.7/site-packages/schedule/__init__.py", line 131, in _run_job
    ret = job.run()
  File "/anaconda3/lib/python3.7/site-packages/schedule/__init__.py", line 411, in run
    ret = self.job_func()
  File "weather.py", line 124, in job
    message = generate_message(user['location'])
  File "weather.py", line 62, in generate_message
    fc = owm.three_hours_forecast(location)
  File "/anaconda3/lib/python3.7/site-packages/pyowm/weatherapi25/owm25.py", line 567, in three_hours_forecast
    _, json_data = self._wapi.cacheable_get_json(uri, params=params)
  File "/anaconda3/lib/python3.7/site-packages/pyowm/commons/http_client.py", line 87, in cacheable_get_json
    status_code, data = self.get_json(uri, params=params, headers=headers)
  File "/anaconda3/lib/python3.7/site-packages/pyowm/commons/http_client.py", line 29, in get_json
    raise api_call_error.APIInvalidSSLCertificateError(str(e))
pyowm.exceptions.api_call_error.APIInvalidSSLCertificateError: Exception in calling OWM Weather API.
Reason: HTTPConnectionPool(host='api.openweathermap.org', port=80): Max retries exceeded with url: /data/2.5/forecast?APPID=08ce08de126e25469062d11550ee8e4c&q=New+York%2C+New+York&lang=en (Caused by NewConnectionError('<urllib3.connection.HTTPConnection object at 0x11e35b7f0>: Failed to establish a new connection: [Errno 8] nodename nor servname provided, or not known'))
Caused by: None
Traceback (most recent call last):
  File "/anaconda3/lib/python3.7/site-packages/urllib3/connection.py", line 159, in _new_conn
    (self._dns_host, self.port), self.timeout, **extra_kw)
  File "/anaconda3/lib/python3.7/site-packages/urllib3/util/connection.py", line 57, in create_connection
    for res in socket.getaddrinfo(host, port, family, socket.SOCK_STREAM):
  File "/anaconda3/lib/python3.7/socket.py", line 748, in getaddrinfo
    for res in _socket.getaddrinfo(host, port, family, type, proto, flags):
socket.gaierror: [Errno 8] nodename nor servname provided, or not known

During handling of the above exception, another exception occurred:

Traceback (most recent call last):
  File "/anaconda3/lib/python3.7/site-packages/urllib3/connectionpool.py", line 600, in urlopen
    chunked=chunked)
  File "/anaconda3/lib/python3.7/site-packages/urllib3/connectionpool.py", line 354, in _make_request
    conn.request(method, url, **httplib_request_kw)
  File "/anaconda3/lib/python3.7/http/client.py", line 1229, in request
    self._send_request(method, url, body, headers, encode_chunked)
  File "/anaconda3/lib/python3.7/http/client.py", line 1275, in _send_request
    self.endheaders(body, encode_chunked=encode_chunked)
  File "/anaconda3/lib/python3.7/http/client.py", line 1224, in endheaders
    self._send_output(message_body, encode_chunked=encode_chunked)
  File "/anaconda3/lib/python3.7/http/client.py", line 1016, in _send_output
    self.send(msg)
  File "/anaconda3/lib/python3.7/http/client.py", line 956, in send
    self.connect()
  File "/anaconda3/lib/python3.7/site-packages/urllib3/connection.py", line 181, in connect
    conn = self._new_conn()
  File "/anaconda3/lib/python3.7/site-packages/urllib3/connection.py", line 168, in _new_conn
    self, "Failed to establish a new connection: %s" % e)
urllib3.exceptions.NewConnectionError: <urllib3.connection.HTTPConnection object at 0x118266b00>: Failed to establish a new connection: [Errno 8] nodename nor servname provided, or not known

During handling of the above exception, another exception occurred:

Traceback (most recent call last):
  File "/anaconda3/lib/python3.7/site-packages/requests/adapters.py", line 449, in send
    timeout=timeout
  File "/anaconda3/lib/python3.7/site-packages/urllib3/connectionpool.py", line 638, in urlopen
    _stacktrace=sys.exc_info()[2])
  File "/anaconda3/lib/python3.7/site-packages/urllib3/util/retry.py", line 398, in increment
    raise MaxRetryError(_pool, url, error or ResponseError(cause))
urllib3.exceptions.MaxRetryError: HTTPConnectionPool(host='api.openweathermap.org', port=80): Max retries exceeded with url: /data/2.5/forecast?APPID=08ce08de126e25469062d11550ee8e4c&q=New+York%2C+New+York&lang=en (Caused by NewConnectionError('<urllib3.connection.HTTPConnection object at 0x118266b00>: Failed to establish a new connection: [Errno 8] nodename nor servname provided, or not known'))

During handling of the above exception, another exception occurred:

Traceback (most recent call last):
  File "/anaconda3/lib/python3.7/site-packages/pyowm/commons/http_client.py", line 25, in get_json
    timeout=self.timeout, verify=self.verify_ssl_certs)
  File "/anaconda3/lib/python3.7/site-packages/requests/api.py", line 75, in get
    return request('get', url, params=params, **kwargs)
  File "/anaconda3/lib/python3.7/site-packages/requests/api.py", line 60, in request
    return session.request(method=method, url=url, **kwargs)
  File "/anaconda3/lib/python3.7/site-packages/requests/sessions.py", line 533, in request
    resp = self.send(prep, **send_kwargs)
  File "/anaconda3/lib/python3.7/site-packages/requests/sessions.py", line 646, in send
    r = adapter.send(request, **kwargs)
  File "/anaconda3/lib/python3.7/site-packages/requests/adapters.py", line 516, in send
    raise ConnectionError(e, request=request)
requests.exceptions.ConnectionError: HTTPConnectionPool(host='api.openweathermap.org', port=80): Max retries exceeded with url: /data/2.5/forecast?APPID=08ce08de126e25469062d11550ee8e4c&q=New+York%2C+New+York&lang=en (Caused by NewConnectionError('<urllib3.connection.HTTPConnection object at 0x118266b00>: Failed to establish a new connection: [Errno 8] nodename nor servname provided, or not known'))

During handling of the above exception, another exception occurred:

Traceback (most recent call last):
  File "weather.py", line 130, in <module>
    schedule.run_pending()
  File "/anaconda3/lib/python3.7/site-packages/schedule/__init__.py", line 493, in run_pending
    default_scheduler.run_pending()
  File "/anaconda3/lib/python3.7/site-packages/schedule/__init__.py", line 78, in run_pending
    self._run_job(job)
  File "/anaconda3/lib/python3.7/site-packages/schedule/__init__.py", line 131, in _run_job
    ret = job.run()
  File "/anaconda3/lib/python3.7/site-packages/schedule/__init__.py", line 411, in run
    ret = self.job_func()
  File "weather.py", line 124, in job
    message = generate_message(user['location'])
  File "weather.py", line 62, in generate_message
    fc = owm.three_hours_forecast(location)
  File "/anaconda3/lib/python3.7/site-packages/pyowm/weatherapi25/owm25.py", line 567, in three_hours_forecast
    _, json_data = self._wapi.cacheable_get_json(uri, params=params)
  File "/anaconda3/lib/python3.7/site-packages/pyowm/commons/http_client.py", line 87, in cacheable_get_json
    status_code, data = self.get_json(uri, params=params, headers=headers)
  File "/anaconda3/lib/python3.7/site-packages/pyowm/commons/http_client.py", line 29, in get_json
    raise api_call_error.APIInvalidSSLCertificateError(str(e))
pyowm.exceptions.api_call_error.APIInvalidSSLCertificateError: Exception in calling OWM Weather API.
Reason: HTTPConnectionPool(host='api.openweathermap.org', port=80): Max retries exceeded with url: /data/2.5/forecast?APPID=08ce08de126e25469062d11550ee8e4c&q=New+York%2C+New+York&lang=en (Caused by NewConnectionError('<urllib3.connection.HTTPConnection object at 0x118266b00>: Failed to establish a new connection: [Errno 8] nodename nor servname provided, or not known'))
Caused by: None
Traceback (most recent call last):
  File "/anaconda3/lib/python3.7/site-packages/urllib3/connectionpool.py", line 384, in _make_request
    six.raise_from(e, None)
  File "<string>", line 2, in raise_from
  File "/anaconda3/lib/python3.7/site-packages/urllib3/connectionpool.py", line 380, in _make_request
    httplib_response = conn.getresponse()
  File "/anaconda3/lib/python3.7/http/client.py", line 1321, in getresponse
    response.begin()
  File "/anaconda3/lib/python3.7/http/client.py", line 296, in begin
    version, status, reason = self._read_status()
  File "/anaconda3/lib/python3.7/http/client.py", line 257, in _read_status
    line = str(self.fp.readline(_MAXLINE + 1), "iso-8859-1")
  File "/anaconda3/lib/python3.7/socket.py", line 589, in readinto
    return self._sock.recv_into(b)
socket.timeout: timed out

During handling of the above exception, another exception occurred:

Traceback (most recent call last):
  File "/anaconda3/lib/python3.7/site-packages/requests/adapters.py", line 449, in send
    timeout=timeout
  File "/anaconda3/lib/python3.7/site-packages/urllib3/connectionpool.py", line 638, in urlopen
    _stacktrace=sys.exc_info()[2])
  File "/anaconda3/lib/python3.7/site-packages/urllib3/util/retry.py", line 367, in increment
    raise six.reraise(type(error), error, _stacktrace)
  File "/anaconda3/lib/python3.7/site-packages/urllib3/packages/six.py", line 686, in reraise
    raise value
  File "/anaconda3/lib/python3.7/site-packages/urllib3/connectionpool.py", line 600, in urlopen
    chunked=chunked)
  File "/anaconda3/lib/python3.7/site-packages/urllib3/connectionpool.py", line 386, in _make_request
    self._raise_timeout(err=e, url=url, timeout_value=read_timeout)
  File "/anaconda3/lib/python3.7/site-packages/urllib3/connectionpool.py", line 306, in _raise_timeout
    raise ReadTimeoutError(self, url, "Read timed out. (read timeout=%s)" % timeout_value)
urllib3.exceptions.ReadTimeoutError: HTTPConnectionPool(host='api.openweathermap.org', port=80): Read timed out. (read timeout=2)

During handling of the above exception, another exception occurred:

Traceback (most recent call last):
  File "/anaconda3/lib/python3.7/site-packages/pyowm/commons/http_client.py", line 25, in get_json
    timeout=self.timeout, verify=self.verify_ssl_certs)
  File "/anaconda3/lib/python3.7/site-packages/requests/api.py", line 75, in get
    return request('get', url, params=params, **kwargs)
  File "/anaconda3/lib/python3.7/site-packages/requests/api.py", line 60, in request
    return session.request(method=method, url=url, **kwargs)
  File "/anaconda3/lib/python3.7/site-packages/requests/sessions.py", line 533, in request
    resp = self.send(prep, **send_kwargs)
  File "/anaconda3/lib/python3.7/site-packages/requests/sessions.py", line 646, in send
    r = adapter.send(request, **kwargs)
  File "/anaconda3/lib/python3.7/site-packages/requests/adapters.py", line 529, in send
    raise ReadTimeout(e, request=request)
requests.exceptions.ReadTimeout: HTTPConnectionPool(host='api.openweathermap.org', port=80): Read timed out. (read timeout=2)

During handling of the above exception, another exception occurred:

Traceback (most recent call last):
  File "weather.py", line 130, in <module>
    schedule.run_pending()
  File "/anaconda3/lib/python3.7/site-packages/schedule/__init__.py", line 493, in run_pending
    default_scheduler.run_pending()
  File "/anaconda3/lib/python3.7/site-packages/schedule/__init__.py", line 78, in run_pending
    self._run_job(job)
  File "/anaconda3/lib/python3.7/site-packages/schedule/__init__.py", line 131, in _run_job
    ret = job.run()
  File "/anaconda3/lib/python3.7/site-packages/schedule/__init__.py", line 411, in run
    ret = self.job_func()
  File "weather.py", line 124, in job
    message = generate_message(user['location'])
  File "weather.py", line 62, in generate_message
    fc = owm.three_hours_forecast(location)
  File "/anaconda3/lib/python3.7/site-packages/pyowm/weatherapi25/owm25.py", line 567, in three_hours_forecast
    _, json_data = self._wapi.cacheable_get_json(uri, params=params)
  File "/anaconda3/lib/python3.7/site-packages/pyowm/commons/http_client.py", line 87, in cacheable_get_json
    status_code, data = self.get_json(uri, params=params, headers=headers)
  File "/anaconda3/lib/python3.7/site-packages/pyowm/commons/http_client.py", line 31, in get_json
    raise api_call_error.APICallTimeoutError('API call timeouted')
pyowm.exceptions.api_call_error.APICallTimeoutError: Exception in calling OWM Weather API.
Reason: API call timeouted
Caused by: None
Traceback (most recent call last):
  File "weather.py", line 130, in <module>
    schedule.run_pending()
  File "/anaconda3/lib/python3.7/site-packages/schedule/__init__.py", line 493, in run_pending
    default_scheduler.run_pending()
  File "/anaconda3/lib/python3.7/site-packages/schedule/__init__.py", line 78, in run_pending
    self._run_job(job)
  File "/anaconda3/lib/python3.7/site-packages/schedule/__init__.py", line 131, in _run_job
    ret = job.run()
  File "/anaconda3/lib/python3.7/site-packages/schedule/__init__.py", line 411, in run
    ret = self.job_func()
  File "weather.py", line 125, in job
    send(message, user['phone_number'], user['carrier'])
  File "weather.py", line 45, in send
    server.login(auth[0], auth[1])
  File "/anaconda3/lib/python3.7/smtplib.py", line 730, in login
    raise last_exception
  File "/anaconda3/lib/python3.7/smtplib.py", line 721, in login
    initial_response_ok=initial_response_ok)
  File "/anaconda3/lib/python3.7/smtplib.py", line 642, in auth
    raise SMTPAuthenticationError(code, resp)
smtplib.SMTPAuthenticationError: (535, b'5.7.8 Username and Password not accepted. Learn more at\n5.7.8  https://support.google.com/mail/?p=BadCredentials 24sm4880615qtu.17 - gsmtp')
